Workbook
Name \p: #N/A
Name _1: 'NF-2200-PID-01'!#REF!
Name _1: 'PID-0101'!#REF!
Name _1: 'PID-0101 (2)'!#REF!
Name _1: #REF!
Name _2: 'NF-2200-PID-01'!#REF!
Name _2: 'PID-0101'!#REF!
Name _2: 'PID-0101 (2)'!#REF!
Name _2: #REF!
Name _222: 'NF-2200-PID-01'!#REF!
Name _222: 'PID-0101'!#REF!
Name _222: 'PID-0101 (2)'!#REF!
Name _222: #REF!
Name _a5: [1]!Module1.UNITOK
Name _a5: #REF!
Name _a5: [1]!Module1.UNITOK
Name _a5: [1]!Module1.UNITOK
Name _a5: [1]!Module1.UNITOK
Name _a6: [2]!UNITOK
Name _a6: #REF!
Name _a6: [2]!UNITOK
Name _a6: [2]!UNITOK
Name _a6: [2]!UNITOK
Name _BTM150: 'NF-2200-PID-01'!#REF!
Name _BTM150: 'PID-0101'!#REF!
Name _BTM150: 'PID-0101 (2)'!#REF!
Name _BTM150: #REF!
Name _BTM200: 'NF-2200-PID-01'!#REF!
Name _BTM200: 'PID-0101'!#REF!
Name _BTM200: 'PID-0101 (2)'!#REF!
Name _BTM200: #REF!
Name _BTM50: 'NF-2200-PID-01'!#REF!
Name _BTM50: 'PID-0101'!#REF!
Name _BTM50: 'PID-0101 (2)'!#REF!
Name _BTM50: #REF!
Name _CON1: 'NF-2200-PID-01'!#REF!
Name _CON1: 'PID-0101'!#REF!
Name _CON1: 'PID-0101 (2)'!#REF!
Name _CON1: #REF!
Name _CON2: 'NF-2200-PID-01'!#REF!
Name _CON2: 'PID-0101'!#REF!
Name _CON2: 'PID-0101 (2)'!#REF!
Name _CON2: #REF!
Name _EXC1: 'NF-2200-PID-01'!#REF!
Name _EXC1: 'PID-0101'!#REF!
Name _EXC1: 'PID-0101 (2)'!#REF!
Name _EXC1: #REF!
Name _EXC2: 'NF-2200-PID-01'!#REF!
Name _EXC2: 'PID-0101'!#REF!
Name _EXC2: 'PID-0101 (2)'!#REF!
Name _EXC2: #REF!
Name _hom2: 'NF-2200-PID-01'!#REF!
Name _hom2: 'PID-0101'!#REF!
Name _hom2: 'PID-0101 (2)'!#REF!
Name _hom2: #REF!
Name _msl100: 'NF-2200-PID-01'!#REF!
Name _msl100: 'PID-0101'!#REF!
Name _msl100: 'PID-0101 (2)'!#REF!
Name _msl100: #REF!
Name _msl200: 'NF-2200-PID-01'!#REF!

Sheet Cover sheet
A6: Project
A7: Project No.
A8: Originating Company
A9: Document Title | F9: Line List
A10: Document Number
A11: Document Revision
A12: Document Status | F12: APR
A13: Document type | F13: List
A14: Originator / Author | F14: DJM
A15: Issue Date
A27: P1 | C27: Issued for Approval | F27: DJM | G27: HRS | H27: SBR
A28: Rev # | B28: Issue Date | C28: Description/Reason for Change | F28: Originator | G28: Reviewer | H28: Approver

Sheet Front page
B2: Project Number | G2: : | H2: ='Cover sheet'!$F$7 -> 0
B3: Project Title | G3: : | H3: ='Cover sheet'!$F$6 -> 0
B4: Document number | G4: : | H4: ='Cover sheet'!$F$10 -> 0
B5: Document Revision | G5: : | H5: ='Cover sheet'!$F$11 -> 0 | K5: Date | M5: : | N5: ='Cover sheet'!B27 -> 0
C8: Nomenclatur for Equipment List
C12: V | E12: : | F12: Vertical | M12: TBD | O12: : | P12: To Be Decided
C14: H | D14: H | E14: : | F14: Horizontal | M14: CTS | O14: : | P14: Client To Specify
C16: FL | E16: : | F16: Flameproof | M16: DTCB | O16: : | P16: Dished Top Conical Bottom
C18: ST | E18: : | F18: Standard | M18: FBCT | O18: : | P18: Flat Bottom Conical Top
C20: B/O | E20: : | F20: Bought Out | M20: VDE | O20: : | P20: Vertical Dished End
C22: FAB | E22: : | F22: Fabricated | M22: FBFT | O22: : | P22: Flat Bottom Flat Top
C24: TL | E24: : | F24: Tile Lined | M24: FTCB | O24: : | P24: Flat Top Conical Bottom
C26: GL | E26: : | F26: Glass Lined | M26: T | O26: : | P26: Total
C28: RL | E28: : | F28: Rubber Lined | M28: W | O28: : | P28: Working
C30: BR | E30: : | F30: Brick Lined | M30: SB | O30: : | P30: Stand-by
C32: NHZ | E32: : | F32: Non Hazardous | M32: L | O32: : | P32: Liquid
C34: HZ | E34: : | F34: Hazardous | M34: G | O34: : | P34: Gas
C36: Y | E36: : | F36: Yes | M36: S | O36: : | P36: Solid
C38: N | E38: : | F38: No | M38: VF | O38: : | P38: Variable Frequency
C40: EP | E40: : | F40: Emergency Power
A48: P1 | C48: ='Cover sheet'!B27 -> 0 | G48: Issued for Approval | Q48: DJM | T48: HRS | W48: THS
A49: Rev # | C49: Issue Date | G49: Description / Reason for Change | Q49: Originator | T49: Reviewer | W49: Approver

Sheet NF-2200-PID-01
A1: Line List
A3: Sr. No | C3: P & ID Number | I3: Service Code | M3: Line number | Q3: Nominal pipe size mm | U3: Pipe specs MOC | X3: Fluid State | AA3: Location | AW3: Spec. Gravity | AZ3: Pressure bar (g) | BF3: Temperature °C | BL3: Electrical Continuity | BP3: Tracing / Jacketing | BT3: Insulation | BX3: Hazardous H / NH | CA3: Remark
AA5: From | AL5: To | AZ5: Nor. | BB5: Max. | BD5: Des. | BF5: Nor. | BH5: Max. | BJ5: Des. | BT5: Class | BV5: mm
A6: 1 | C6: 001-4030 | I6: PNA/MIAK/ MCH/CHX | M6: NO LINE NO IN AS BUILT P&ID OF LIPL | Q6: 50/80 | U6: CS/SS | X6: L | AA6: 1436R32 | AL6: EXISTING LINE JH:4030:001-L023-50/80-SS/BD-J-PNA MIAK/MCH/CHX | BF6: 120 | BH6: 125 | BJ6: 130 | BL6: CTC | BP6: YES | BT6: HOLD | BV6: HOLD | BX6: H | CA6: 1) Steam Tracing / * CTC 2) New line in VCare SOW 3) Line no to be given by LIPL
A7: 2 | C7: 001-4030 | I7: PNA/MIAK/ MCH/CHX | M7: LO46 | Q7: 50/80 | U7: CS/SS | X7: L | AA7: 1436F32 | AL7: 1456R01 | BF7: 120 | BH7: 125 | BJ7: 130 | BL7: CTC | BP7: YES | BT7: # | BV7: # | BX7: H | CA7: 1) #: Not in Vcare SOW 2) Existing line of LIPL
C8: 001-4030 | I8: PNA/MIAK/ MCH/CHX | M8: LO23 | Q8: 50/80 | U8: CS/SS | X8: L | AA8: 1436F32 | AL8: 1441R04 | BF8: 120 | BH8: 125 | BJ8: 130 | BL8: CTC | BP8: YES | BT8: # | BV8: # | BX8: H | CA8: 1) #: Not in Vcare SOW 2) Existing line of LIPL
A9: 4 | C9: 002-4030 | I9: 4030 | M9: LOXX / NO LINE NO | Q9: 50 | U9: CS | X9: L | AA9: 1441R04 | AL9: 1456F01 | BF9: 120 | BH9: 125 | BJ9: 130 | BL9: CTC | BP9: YES | BT9: HOLD | BV9: HOLD | BX9: H | CA9: 1) Electrical tracing / * CTC, 2) Line in VCare SOW, 3) Line no to be given by LIPL
A10: 7 | C10: 003-4030 | I10: 4030 | M10: LOXX / NO LINE NO | Q10: 25 | U10: CS | X10: L | AA10: LO-59-BD-WATER | AL10: LO38-50-BD-WATER | BF10: 120 | BH10: 125 | BJ10: 130 | BL10: CTC | BP10: YES | BT10: HOLD | BV10: HOLD | BX10: H | CA10: 1) Electrical tracing / * CTC, 2) Line in VCare SOW, 3) Line no to be given by LIPL
A11: 8 | C11: 003-4030 | I11: 4030 | M11: L060 | Q11: 50 | U11: CS | X11: L | AA11: 1436B09 | AL11: LO38-50-BD-4030 | BF11: 120 | BH11: 125 | BJ11: 130 | BL11: CTC | BP11: YES | BT11: HOLD | BV11: HOLD | BX11: H | CA11: 1) Electrical tracing / * CTC, 2) Line in VCare SOW
A12: 9 | C12: 003-4030 | I12: 4030 | M12: L037 | Q12: 50 | U12: CS | X12: L | AA12: 1436P09 via LO38-50-BD-4030 | AL12: 1436B09 | BF12: 120 | BH12: 125 | BJ12: 130 | BL12: CTC | BP12: YES | BT12: HOLD | BV12: HOLD | BX12: H | CA12: 1) Electrical tracing / * CTC, 2) Line in VCare SOW
A13: 10 | C13: 003-4030 | I13: 4030 | M13: L039 | Q13: 50 | U13: CS | X13: L | AA13: LO38-50-BD-4030 | AL13: L055-50-BD-MIAK/MCH/CHX | BF13: 120 | BH13: 125 | BJ13: 130 | BL13: CTC | BP13: YES | BT13: HOLD | BV13: HOLD | BX13: H | CA13: 1) Electrical tracing / * CTC, 2) Line in VCare SOW
A14: 11 | C14: 004-4030 | I14: MIAK | M14: LOXX / NO LINE NO | Q14: 50 | U14: CS | X14: L | AA14: L046-50-BD | AL14: 1456B04 | BF14: 120 | BH14: 125 | BJ14: 130 | BL14: CTC | BP14: YES | BT14: HOLD | BV14: HOLD | BX14: H
A15: 12 | C15: 008-4030 | I15: 4030 | M15: LOXX / NO LINE NO | Q15: 50 | U15: CS / CTC | X15: L | AA15: L012-50-BD1 | AL15: 1456F01 | BF15: 120 | BH15: 125 | BJ15: 130 | BL15: CTC | BP15: YES | BT15: HOLD | BV15: HOLD | BX15: H
A16: 13 | C16: 011-4030 | I16: 4030 | M16: L015 | Q16: 50 | U16: CS | X16: L | AA16: SUMP | AL16: 1441R04 | BF16: 120 | BH16: 125 | BJ16: 130 | BL16: CTC | BP16: YES | BT16: HOLD | BV16: HOLD | BX16: H | CA16: 1) Electrical tracing / * CTC, 2) Line in VCare SOW
A17: 14 | C17: 011-4030 | I17: 4030 | M17: L067 | Q17: 50 | U17: CS | X17: L | AA17: SUMP | AL17: 1456R01 | BF17: 120 | BH17: 125 | BJ17: 130 | BL17: CTC | BP17: YES | BT17: HOLD | BV17: HOLD | BX17: H | CA17: 1) #: Not in Vcare SOW 2) Existing line of LIPL
A18: 15 | BX18: H
A19: 16 | BX19: H
A20: 17 | BX20: H
A21: 18 | BX21: H
A22: 19 | BX22: H
A23: 20
A24: 21
A25: 22
A26: 24
A27: 25
A28: 26
A30: NOTES :
A31: 1) Line number shall be updated / changed in final P&ID revision.
C34: `@Vacre-global
C35: This document is issued for the party which commissioned it and for specific purposes connected with the captioned project only. It should not be relied upon by any other party or used for any other purpose.
C36: We accept no responsibility for the consequences of this document being relied upon by any other party, or being used for any other purpose, or containing any error or omission which is due to an error or omission in data supplied to us by other parties.
U37: Client | AL37: Rev | AN37: Date | AR37: Prep | AU37: Description | BF37: Chk'd | BI37: App'd | BL37: Title | CB37: Prep | CF37: =$AR38 -> #REF!
AL38: =#REF! -> #REF! | AN38: =#REF! -> #REF! | AR38: =#REF! -> #REF! | AU38: =#REF! -> #REF! | BF38: =#REF! -> #REF! | BI38: =#REF! -> #REF! | CB38: Chk'd | CF38: =$BF38 -> #REF!
BN39: Line List | CB39: App'd | CF39: =$BI38 -> #REF!
H40: Vcare Engineering pvt ltd | AA40: LANXESS INDIA PVT LTD | CC40: Sheet No: 01 of 11
H41: 301/A, Block E, Notus Pride IT Park, | AA41: Jhagadia, Bharuch, Gujarat
H42: Sarabhai Campus, Subhanpura Rd, | AA42: India | BL42: Document number | CB42: Security | CF42: Status | CI42: Rev
H43: Gorwa,Vadodara, Gujarat 390023 | BM43: =#REF! -> #REF! | CB43: STD | CF43: APR | CI43: =#REF! -> #REF!
CV48: code | CW48: pressure | CZ48: temperature
CW49: opt | CX49: max | CY49: design | CZ49: opt | DA49: max | DB49: design
...

Sheet page 1
E2: EQUIPMENT LIST
B3: DOC. NO.: | E3: CLIENT: ELANTAS Beck India Limited. | G3: PAGE 1 OF 3
B4: CLIENT PROJECT NO.: Ank/Plan-C/443 VCARE PROJECT NO.: VCE-EDS-0685 | E4: PROJECT: Plan - C- Detail Engineering, Ankleshwar | G4: REV. 0
B7: LINE LIST
B16: 0 | C16: 46293 | D16: IFR – Issue for Review | F16: SS | G16: SV | H16: KV
B17: REV. | C17: DATE | D17: PURPOSE | F17: PREPARED BY | G17: CHECKED BY | H17: APPROVED BY

Sheet PID-0101
A1: Line List
A3: Sr. No | C3: Drawing Number | I3: Nominal pipe size mm | M3: Service Code | Q3: P & ID Number | R3: Line number | V3: Pipe specs MOC | Z3: Fluid State | AC3: Rating | AD3: Pipe Spec | AE3: Pipe Thickness | AG3: Location | BC3: Spec. Gravity | BF3: Pressure bar (g) | BJ3: Temperature °C | BN3: Electrical Continuity | BR3: Tracing / Jacketing | BV3: Insulation | BZ3: Hazardous H / NH | CC3: Remark
AG5: From | AR5: To | BF5: Nor. | BH5: Des. | BJ5: Nor. | BL5: Des. | BV5: Class | BX5: mm
A7: 1 | C7: WCES26-007-PR-PID-001 | I7: 3" | M7: NH3 | Q7: 001 | R7: 10101 | V7: SS0 | Y7: 3001BK10S | Z7: L | AC7: 300# | AD7: 1AN | AE7: 10S | AF7: 3"-NH3-001-10101-SS0-3001BK10S-N-0.0 | AG7: Tanker | AR7: P-101A | BC7: =680/1000 -> 0.68 | BF7: 8-14 | BH7: 25 | BJ7: 40 | BL7: 65 | BN7: - | BR7: - | BV7: N | BX7: 0.0
A8: =A7+1 -> 2 | C8: WCES26-007-PR-PID-001 | I8: 3" | M8: NH3 | Q8: 001 | R8: 10102 | V8: SS0 | Y8: 3001BK10S | Z8: L | AC8: 300# | AD8: 1AN | AE8: 10S | AF8: 3"-NH3-001-10102-SS0-3001BK10S-N-0.0 | AG8: 3''-NH3-001-10101-SS0-30010S1AN-N-0.0 | AR8: P-101B | BC8: =680/1000 -> 0.68 | BF8: 8-14 | BH8: 25 | BJ8: 40 | BL8: 65 | BN8: - | BR8: - | BV8: N | BX8: 0.0
A9: =A8+1 -> 3 | C9: WCES26-007-PR-PID-001 | I9: 2" | M9: NH3 | Q9: 001 | R9: 10103 | V9: SS0 | Y9: 3001BK40S | Z9: L | AC9: 300# | AD9: 1AN | AE9: 10S | AF9: 2"-NH3-001-10103-SS0-3001BK40S-N-0.0 | AG9: 2"-NH3-001-10104-SS0-3001BK40S-N-0.0 | AR9: V-101B | BC9: =680/1000 -> 0.68 | BF9: 8-14 | BH9: 25 | BJ9: 40 | BL9: 65 | BN9: - | BR9: - | BV9: N | BX9: 0.0
A10: =A9+1 -> 4 | C10: WCES26-007-PR-PID-001 | I10: 2" | M10: NH3 | Q10: 001 | R10: 10104 | V10: SS0 | Y10: 3001BK40S | Z10: L | AC10: 300# | AD10: 1AN | AE10: 10S | AF10: 2"-NH3-001-10104-SS0-3001BK40S-N-0.0 | AG10: P-101A/B | AR10: V-101A | BC10: =680/1000 -> 0.68 | BF10: 8-14 | BH10: 25 | BJ10: 40 | BL10: 65 | BN10: - | BR10: - | BV10: N | BX10: 0.0
A11: =A10+1 -> 5 | C11: WCES26-007-PR-PID-001 | I11: 2" | M11: NH3 | Q11: 001 | R11: 10115 | V11: SS0 | Y11: 3001BK40S | Z11: V | AC11: 300# | AD11: 1AN | AE11: 10S | AF11: 2"-NH3-001-10115-SS0-3001BK40S-N-0.0 | AG11: V-101A | AR11: 2"-NH3 -001-10116-SS0-3001BK40S-N-0.0 | BC11: 0.007 | BF11: 14 | BH11: 25 | BJ11: 40 | BL11: 65 | BN11: - | BR11: - | BV11: N | BX11: 0.0
A12: =A11+1 -> 6 | C12: WCES26-007-PR-PID-001 | I12: 2" | M12: NH3 | Q12: 001 | R12: 10117 | V12: SS0 | Y12: 3001BK40S | Z12: V | AC12: 300# | AD12: 1AN | AE12: 10S | AF12: 2"-NH3-001-10117-SS0-3001BK40S-N-0.0 | AG12: H-101 | AR12: V-101A | BC12: 0.007 | BF12: 14 | BH12: 25 | BJ12: 40 | BL12: 65 | BN12: - | BR12: - | BV12: N | BX12: 0.0
A13: =A12+1 -> 7 | C13: WCES26-007-PR-PID-001 | I13: 2" | M13: NH3 | Q13: 001 | R13: 10137 | V13: SS0 | Y13: 3001BK40S | Z13: L | AC13: 300# | AD13: 1AN | AE13: 10S | AF13: 2"-NH3-001-10137-SS0-3001BK40S-N-0.0 | AG13: P-101B | AR13: 2"-NH3-001-10104-SS0-3001BK40S-N-0.0 | BC13: =680/1000 -> 0.68 | BF13: 8-14 | BH13: 25 | BJ13: 40 | BL13: 65 | BN13: - | BR13: - | BV13: N | BX13: 0.0
A14: =A13+1 -> 8 | C14: WCES26-007-PR-PID-001 | I14: 2" | M14: NH3 | Q14: 001 | R14: 10138 | V14: SS0 | Y14: 3001BK40S | Z14: L | AC14: 300# | AD14: 1AN | AE14: 10S | AF14: 2"-NH3-001-10138-SS0-3001BK40S-N-0.0 | AG14: 3"-NH3-001-10101-SS0-3001BK10S-N-0.0 | AR14: 2"-NH3-001-10104-SS0-3001BK40S-N-0.0 | BC14: =680/1000 -> 0.68 | BF14: 8-14 | BH14: 25 | BJ14: 40 | BL14: 65 | BN14: - | BR14: - | BV14: N | BX14: 0.0
A15: =A14+1 -> 9 | C15: WCES26-007-PR-PID-001 | I15: 2" | M15: NH3 | Q15: 001 | R15: 10116 | V15: SS0 | Y15: 3001BK40S | Z15: V | AC15: 300# | AD15: 1AN | AE15: 10S | AF15: 2"-NH3 -001-10116-SS0-3001BK40S-N-0.0 | AG15: V-101B | AR15: Road tanker | BC15: 0.007 | BF15: 14 | BH15: 25 | BJ15: 40 | BL15: 65 | BN15: - | BR15: - | BV15: N | BX15: 0.0 | CT15: =6.19*0.0012 -> 0.007428
A16: =A15+1 -> 10 | C16: WCES26-007-PR-PID-001 | I16: 2" | M16: NH3 | Q16: 001 | R16: 10118 | V16: SS0 | Y16: 3001BK40S | Z16: V | AC16: 300# | AD16: 1AN | AE16: 10S | AF16: 2"-NH3 -001-10118-SS0-3001BK40S-N-0.0 | AG16: 2"-NH3-001-10117-SS0-3001BK40S-N-0.0 | AR16: V-101B | BC16: 0.007 | BF16: 14 | BH16: 25 | BJ16: 40 | BL16: 65 | BN16: - | BR16: - | BV16: N | BX16: 0.0 | CT16: =6.19/1000 -> 0.00619
A17: =A16+1 -> 11 | C17: WCES26-007-PR-PID-001 | I17: 2" | M17: NH3 | Q17: 001 | R17: 10119 | V17: SS0 | Y17: 3001BK40S | Z17: V | AC17: 300# | AD17: 1AN | AE17: 10S | AF17: 2"-NH3 -001-10119-SS0-3001BK40S-N-0.0 | AG17: V-101A | AR17: PSV Outlet | BC17: 0.007 | BF17: 14 | BH17: 25 | BJ17: 40 | BL17: 65 | BN17: - | BR17: - | BV17: N | BX17: 0.0
A18: =A17+1 -> 12 | C18: WCES26-007-PR-PID-001 | I18: 2" | M18: NH3 | Q18: 001 | R18: 10120 | V18: SS0 | Y18: 3001BK40S | Z18: V | AC18: 300# | AD18: 1AN | AE18: 10S | AF18: 2"-NH3 -001-10120-SS0-3001BK40S-N-0.0 | AG18: V-101A | AR18: PSV Outlet | BC18: 0.007 | BF18: 14 | BH18: 25 | BJ18: 40 | BL18: 65 | BN18: - | BR18: - | BV18: N | BX18: 0.0
A19: =A18+1 -> 13 | C19: WCES26-007-PR-PID-001 | I19: 2" | M19: NH3 | Q19: 001 | R19: 10121 | V19: SS0 | Y19: 3001BK40S | Z19: V | AC19: 300# | AD19: 1AN | AE19: 10S | AF19: 2"-NH3 -001-10121-SS0-3001BK40S-N-0.0 | AG19: V-101B | AR19: PSV Outlet | BC19: 0.007 | BF19: 14 | BH19: 25 | BJ19: 40 | BL19: 65 | BN19: - | BR19: - | BV19: N | BX19: 0.0
A20: =A19+1 -> 14 | C20: WCES26-007-PR-PID-001 | I20: 2" | M20: NH3 | Q20: 001 | R20: 10122 | V20: SS0 | Y20: 3001BK40S | Z20: V | AC20: 300# | AD20: 1AN | AE20: 10S | AF20: 2"-NH3 -001-10122-SS0-3001BK40S-N-0.0 | AG20: V-101B | AR20: PSV Outlet | BC20: 0.007 | BF20: 14 | BH20: 25 | BJ20: 40 | BL20: 65 | BN20: - | BR20: - | BV20: N | BX20: 0.0
A21: =A20+1 -> 15 | C21: WCES26-007-PR-PID-001 | I21: 2" | M21: SER | Q21: 001 | R21: 10007 | V21: CS | Y21: 1501AAXS | Z21: L | AC21: 150# | AD21: 1AA | AE21: XS | AF21: 2"-SER -001-10007-CS-1501AAXS-N-0.0 | AG21: Tie Point | AR21: T-101 | BC21: 1 | BF21: 1.02 | BH21: 5 | BJ21: 45 | BL21: 65 | BN21: - | BR21: - | BV21: N | BX21: 0.0
A22: =A21+1 -> 16 | C22: WCES26-007-PR-PID-001 | I22: 2" | M22: HW | Q22: 001 | R22: 10007 | V22: CS | Y22: 1501AAXS | Z22: L | AC22: 150# | AD22: 1AA | AE22: XS | AF22: 2"-HW -001-10007-CS-1501AAXS-H-1-1/2" | AG22: T-101 | AR22: P-102B | BC22: =974.4/1000 -> 0.9744 | BF22: 1.02 | BH22: 5 | BJ22: 80 | BL22: 120 | BN22: - | BR22: - | BV22: H | BX22: 1-1/2"
A23: =A22+1 -> 17 | C23: WCES26-007-PR-PID-001 | I23: 2" | M23: HW | Q23: 001 | R23: 10003 | V23: CS | Y23: 1501AAXS | Z23: L | AC23: 150# | AD23: 1AA | AE23: XS | AF23: 2"-HW -001-10003-CS-1501AAXS-H-1-1/2" | AG23: 2"-HW -001-10007-CS-1501AAXS-H-1-1/2" | AR23: P-102A | BC23: =974.4/1000 -> 0.9744 | BF23: 1.02 | BH23: 5 | BJ23: 80 | BL23: 120 | BN23: - | BR23: - | BV23: H | BX23: 1-1/2"
A24: =A23+1 -> 18 | C24: WCES26-007-PR-PID-001 | I24: 1-1/2" | M24: HW | Q24: 001 | R24: 10004 | V24: CS | Y24: 1501AAXS | Z24: L | AC24: 150# | AD24: 1AA | AE24: XS | AF24: 1-1/2"-HW -001-10004-CS-1501AAXS-H-1-1/2" | AG24: P-102A | AR24: 1-1/2"-HW -001-10006-CS-1501AAXS-H-1-1/2" | BC24: =974.4/1000 -> 0.9744 | BF24: 1.96 | BH24: 5 | BJ24: 80 | BL24: 120 | BN24: - | BR24: - | BV24: H | BX24: 1-1/2"
A25: =A24+1 -> 19 | C25: WCES26-007-PR-PID-001 | I25: 1-1/2" | M25: HW | Q25: 001 | R25: 10001 | V25: CS | Y25: 1501AAXS | Z25: L | AC25: 150# | AD25: 1AA | AE25: XS | AF25: 1-1/2"-HW -001-10001-CS-1501AAXS-H-1-1/2" | AG25: P-102B | AR25: 1-1/2"-HW -001-10004-CS-1501AAXS-H-1-1/2" | BC25: =974.4/1000 -> 0.9744 | BF25: 1.96 | BH25: 5 | BJ25: 80 | BL25: 120 | BN25: - | BR25: - | BV25: H | BX25: 1-1/2"
A26: =A25+1 -> 20 | C26: WCES26-007-PR-PID-001 | I26: 1-1/2" | M26: HW | Q26: 001 | R26: 10006 | V26: CS | Y26: 1501AAXS | Z26: L | AC26: 150# | AD26: 1AA | AE26: XS | AF26: 1-1/2"-HW -001-10006-CS-1501AAXS-H-1-1/2" | AG26: 1-1/2"-HW -001-10004-CS-1501AAXS-H-1-1/2" | AR26: H-101 | BC26: =974.4/1000 -> 0.9744 | BF26: 1.96 | BH26: 5 | BJ26: 80 | BL26: 120 | BN26: - | BR26: - | BV26: H | BX26: 1-1/2"
A27: =A26+1 -> 21 | C27: WCES26-007-PR-PID-001 | I27: 1-1/2" | M27: HW | Q27: 001 | R27: 10002 | V27: CS | Y27: 1501AAXS | Z27: L | AC27: 150# | AD27: 1AA | AE27: XS | AF27: 1-1/2"-HW -001-10002-CS-1501AAXS-H-1-1/2" | AG27: H-101 | AR27: T-101 | BC27: =974.4/1000 -> 0.9744 | BF27: 1.96 | BH27: 5 | BJ27: 80 | BL27: 120 | BN27: - | BR27: - | BV27: H | BX27: 1-1/2"
A28: =A27+1 -> 22 | C28: WCES26-007-PR-PID-001 | I28: 2" | M28: NH3 | Q28: 001 | R28: 10108 | V28: SS0 | Y28: 3001BK40S | Z28: L | AC28: 300# | AD28: 1AN | AE28: 10S | AF28: 2"-NH3-001-10108-SS0-3001BK40S-N-0.0 | AG28: V-101A | AR28: H-101 | BC28: =680/1000 -> 0.68 | BF28: 8-14 | BH28: 25 | BJ28: 40 | BL28: 65 | BN28: - | BR28: - | BV28: N | BX28: 0.0
A29: =A28+1 -> 23 | C29: WCES26-007-PR-PID-001 | I29: 2" | M29: NH3 | Q29: 001 | R29: 10106 | V29: SS0 | Y29: 3001BK40S | Z29: L | AC29: 300# | AD29: 1AN | AE29: 10S | AF29: 2"-NH3-001-10106-SS0-3001BK40S-N-0.0 | AG29: V-101B | AR29: H-101 | BC29: =680/1000 -> 0.68 | BF29: 8-14 | BH29: 25 | BJ29: 40 | BL29: 65 | BN29: - | BR29: - | BV29: N | BX29: 0.0
A30: =A29+1 -> 24 | C30: WCES26-007-PR-PID-001 | I30: 2" | M30: NH3 | Q30: 001 | R30: 10111 | V30: SS0 | Y30: 3001BK40S | Z30: V | AC30: 300# | AD30: 1AN | AE30: 10S | AF30: 2"-NH3-001-10111-SS0-3001BK40S-N-0.0 | AG30: V-101B | AR30: 2"-NH3-001-10136-SS0-3001BK40S-N-0.0 | BC30: 0.007 | BF30: 14 | BH30: 25 | BJ30: 40 | BL30: 65 | BN30: - | BR30: - | BV30: N | BX30: 0.0
A31: =A30+1 -> 25 | C31: WCES26-007-PR-PID-001 | I31: 2" | M31: NH3 | Q31: 001 | R31: 10136 | V31: SS0 | Y31: 3001BK40S | Z31: V | AC31: 300# | AD31: 1AN | AE31: 10S | AF31: 2"-NH3-001-10136-SS0-3001BK40S-N-0.0 | AG31: 2"-NH3-001-10110-SS0-3001BK40S-N-0.0 | AR31: TO PLANT | BC31: 0.007 | BF31: 14 | BH31: 25 | BJ31: 40 | BL31: 65 | BN31: - | BR31: - | BV31: N | BX31: 0.0
A32: =A31+1 -> 26 | C32: WCES26-007-PR-PID-001 | I32: 2" | M32: NH3 | Q32: 001 | R32: 10110 | V32: SS0 | Y32: 3001BK40S | Z32: V | AC32: 300# | AD32: 1AN | AE32: 10S | AF32: 2"-NH3-001-10110-SS0-3001BK40S-N-0.0 | AG32: 2"-NH3 -001-10116-SS0-3001BK40S-N-0.0 | AR32: 2"-NH3-001-10136-SS0-3001BK40S-N-0.0 | BC32: 0.007 | BF32: 14 | BH32: 25 | BJ32: 40 | BL32: 65 | BN32: - | BR32: - | BV32: N | BX32: 0.0
A33: =A32+1 -> 27 | C33: WCES26-007-PR-PID-001 | I33: 2" | M33: N2 | Q33: 001 | R33: 10106 | V33: SS0A | Y33: 1501AK40S | Z33: V | AC33: 150# | AD33: 1AK | AE33: 40S | AF33: 2"-N2-001-10106-SS0A-1501AK40S-N-0.0 | AG33: 2"-NH3-001-10110-SS0-3001BK40S-N-0.0 | AR33: 2"-NH3-001-10110-SS0-3001BK40S-N-0.0 | BC33: 0.97 | BF33: 4.5 | BH33: 7 | BJ33: 50 | BL33: 65 | BN33: - | BR33: - | BV33: N | BX33: 0.0
A34: =A33+1 -> 28 | C34: WCES26-007-PR-PID-001 | I34: 1" | M34: NH3 | Q34: 001 | R34: 10125 | V34: SS0 | Y34: 3001BK40S | Z34: V | AC34: 300# | AD34: 1AN | AE34: 10S | AF34: 1"-NH3-001-10125-SS0-3001BK40S-N-0.0 | AG34: 2"-NH3-001-10111-SS0-3001BK40S-N-0.0 | AR34: GC Analyzer | BC34: 0.007 | BF34: 14 | BH34: 25 | BJ34: 40 | BL34: 65 | BN34: - | BR34: - | BV34: N | BX34: 0.0
A35: =A34+1 -> 29 | C35: WCES26-007-PR-PID-001 | I35: 2" | M35: NH3 | Q35: 001 | R35: 10112 | V35: SS0 | Y35: 3001BK40S | Z35: V | AC35: 300# | AD35: 1AN | AE35: 10S | AF35: 2"-NH3-001-10112-SS0-3001BK40S-N-0.0 | AG35: 2"-NH3-001-10105-SS0-3001BK40S-N-0.0 | AR35: 2"-NH3-001-10110-SS0-3001BK40S-N-0.0 | BC35: 0.007 | BF35: 14 | BH35: 25 | BJ35: 40 | BL35: 65 | BN35: - | BR35: - | BV35: N | BX35: 0.0
A36: =A35+1 -> 30 | C36: WCES26-007-PR-PID-001 | I36: 1" | M36: NH3 | Q36: 001 | R36: 10124 | V36: SS0 | Y36: 3001BK40S | Z36: V | AC36: 300# | AD36: 1AN | AE36: 10S | AF36: 1"-NH3-001-10124-SS0-3001BK40S-N-0.0 | AG36: 2"-NH3-001-10112-SS0-3001BK40S-N-0.0 | AR36: GC Analyzer | BC36: 0.007 | BF36: 14 | BH36: 25 | BJ36: 40 | BL36: 65 | BN36: - | BR36: - | BV36: N | BX36: 0.0
A37: =A36+1 -> 31 | C37: WCES26-007-PR-PID-001 | I37: 1" | M37: NH3 | Q37: 001 | R37: 10126 | V37: SS0 | Y37: 3001BK40S | Z37: V | AC37: 300# | AD37: 1AN | AE37: 10S | AF37: 1"-NH3-001-10126-SS0-3001BK40S-N-0.0 | AG37: GC Analyzer | AR37: 2"-NH3-001-10105-SS0-3001BK40S-N-0.0 | BC37: 0.007 | BF37: 14 | BH37: 25 | BJ37: 40 | BL37: 65 | BN37: - | BR37: - | BV37: N | BX37: 0.0
A38: =A37+1 -> 32 | C38: WCES26-007-PR-PID-001 | I38: 2" | M38: NH3 | Q38: 001 | R38: 10105 | V38: SS0 | Y38: 3001BK40S | Z38: V | AC38: 300# | AD38: 1AN | AE38: 10S | AF38: 2"-NH3-001-10105-SS0-3001BK40S-N-0.0 | AG38: 2"-NH3-001-10111-SS0-3001BK40S-N-0.0 | AR38: 4"-NH3-001-10108-SS0-3001BK10S-N-0.0 | BC38: 0.007 | BF38: 14 | BH38: 25 | BJ38: 40 | BL38: 65 | BN38: - | BR38: - | BV38: N | BX38: 0.0
A39: =A38+1 -> 33 | C39: WCES26-007-PR-PID-001 | I39: 4" | M39: NH3 | Q39: 001 | R39: 10108 | V39: SS0 | Y39: 3001BK10S | Z39: V | AC39: 300# | AD39: 1AN | AE39: 10S | AF39: 4"-NH3-001-10108-SS0-3001BK10S-N-0.0 | AG39: HEADER | AR39: C-103 | BC39: 0.007 | BF39: 14 | BH39: 25 | BJ39: 40 | BL39: 65 | BN39: - | BR39: - | BV39: N | BX39: 0.0
A40: =A39+1 -> 34 | C40: WCES26-007-PR-PID-001 | I40: 1/2" | M40: N2 | Q40: 001 | R40: 10105 | V40: SS0A | Y40: 1501AK80S | Z40: V | AC40: 150# | AD40: 1AK | AE40: 40S | AF40: 1/2"-N2-001-10105-SS0A-1501AK80S-N-0.0 | AG40: 2"-N2-001-10110-SS0A-1501AK40S-N-0.0 | AR40: 2"-NH3-001-10136-SS0-3001BK40S-N-0.0 | BC40: 0.97 | BF40: 4.5 | BH40: 7 | BJ40: 50 | BL40: 65 | BN40: - | BR40: - | BV40: N | BX40: 0.0
A41: =A40+1 -> 35 | C41: WCES26-007-PR-PID-001 | I41: 2" | M41: N2 | Q41: 001 | R41: 10104 | V41: SS0A | Y41: 1501AK40S | Z41: V | AC41: 150# | AD41: 1AK | AE41: 40S | AF41: 2"-N2-001-10104-SS0A-1501AK40S-N-0.0 | AG41: 2"-N2-001-10110-SS0A-1501AK40S-N-0.0 | AR41: 2"-NH3-001-10111-SS0-3001BK40S-N-0.0 | BC41: 0.97 | BF41: 4.5 | BH41: 7 | BJ41: 50 | BL41: 65 | BN41: - | BR41: - | BV41: N | BX41: 0.0
... A56: =A55+1 -> 50 | C56: WCES26-007-PR-PID-002 | I56: 4" | M56: EHG | Q56: 002 | R56: 10109 | V56: FRP | Y56: 150FRPXX | Z56: V | AC56: 150# | AD56: FRP | AE56: XX | AF56: 4"-EHG-002-10109-FRP-150FRPXX-N-0.0 | AG56: C-103 | AR56: VENT TO SAFE LOCATION | BC56: 0.62 | BF56: 1.033 | BH56: 1.5 | BJ56: 45 | BL56: 50 | BN56: - | BR56: - | BV56: N | BX56: 0.0
R57: 10130
...

Sheet PID-0101 (2)
A1: Line List
A3: Sr. No | B3: Drawing Number | C3: Nominal pipe size mm | D3: Service Code | E3: Line number | F3: Pipe specs MOC | G3: Fluid State | H3: Rating | I3: Pipe Spec | J3: Pipe Thickness | L3: Location | N3: Spec. Gravity | O3: Pressure bar (g) | Q3: Temperature °C | S3: Electrical Continuity | T3: Tracing / Jacketing | U3: Insulation | W3: Hazardous H / NH | X3: Remark
L5: From | M5: To | O5: Nor. | P5: Des. | Q5: Nor. | R5: Des. | U5: Class | V5: mm
A701: NOTES :
A702: 1) Line number shall be updated / changed in final P&ID revision.
B705: `@Vacre-global
B706: This document is issued for the party which commissioned it and for specific purposes connected with the captioned project only. It should not be relied upon by any other party or used for any other purpose.
B707: We accept no responsibility for the consequences of this document being relied upon by any other party, or being used for any other purpose, or containing any error or omission which is due to an error or omission in data supplied to us by other parties.
F708: Client | M708: Rev | Q708: Chk'd | S708: Title
M709: 0 | Q709: SV
B711: Vcare Engineering pvt ltd
B712: 301/A, Block E, Notus Pride IT Park,
B713: Sarabhai Campus, Subhanpura Rd, | S713: Document number
B714: Gorwa,Vadodara, Gujarat 390023

Sheet 1003

Sheet Sheet4
